2020-04-24 17:34:06,848 ERROR: Exception on /login [GET] [in /home/lutz/Development/databas/venv/lib/python3.6/site-packages/flask/app.py:1891]
Traceback (most recent call last):
  File "/home/lutz/Development/databas/venv/lib/python3.6/site-packages/sqlalchemy/engine/base.py", line 1248, in _execute_context
    cursor, statement, parameters, context
  File "/home/lutz/Development/databas/venv/lib/python3.6/site-packages/sqlalchemy/engine/default.py", line 588, in do_execute
    cursor.execute(statement, parameters)
sqlite3.OperationalError: no such column: user.isAdmin

The above exception was the direct cause of the following exception:

Traceback (most recent call last):
  File "/home/lutz/Development/databas/venv/lib/python3.6/site-packages/flask/app.py", line 2446, in wsgi_app
    response = self.full_dispatch_request()
  File "/home/lutz/Development/databas/venv/lib/python3.6/site-packages/flask/app.py", line 1951, in full_dispatch_request
    rv = self.handle_user_exception(e)
  File "/home/lutz/Development/databas/venv/lib/python3.6/site-packages/flask/app.py", line 1820, in handle_user_exception
    reraise(exc_type, exc_value, tb)
  File "/home/lutz/Development/databas/venv/lib/python3.6/site-packages/flask/_compat.py", line 39, in reraise
    raise value
  File "/home/lutz/Development/databas/venv/lib/python3.6/site-packages/flask/app.py", line 1947, in full_dispatch_request
    rv = self.preprocess_request()
  File "/home/lutz/Development/databas/venv/lib/python3.6/site-packages/flask/app.py", line 2241, in preprocess_request
    rv = func()
  File "/home/lutz/Development/databas/app/routes.py", line 14, in before_request
    if current_user.is_authenticated:
  File "/home/lutz/Development/databas/venv/lib/python3.6/site-packages/werkzeug/local.py", line 347, in __getattr__
    return getattr(self._get_current_object(), name)
  File "/home/lutz/Development/databas/venv/lib/python3.6/site-packages/werkzeug/local.py", line 306, in _get_current_object
    return self.__local()
  File "/home/lutz/Development/databas/venv/lib/python3.6/site-packages/flask_login/utils.py", line 26, in <lambda>
    current_user = LocalProxy(lambda: _get_user())
  File "/home/lutz/Development/databas/venv/lib/python3.6/site-packages/flask_login/utils.py", line 346, in _get_user
    current_app.login_manager._load_user()
  File "/home/lutz/Development/databas/venv/lib/python3.6/site-packages/flask_login/login_manager.py", line 318, in _load_user
    user = self._user_callback(user_id)
  File "/home/lutz/Development/databas/app/models.py", line 82, in load_user
    return User.query.get(int(id))
  File "/home/lutz/Development/databas/venv/lib/python3.6/site-packages/sqlalchemy/orm/query.py", line 1004, in get
    return self._get_impl(ident, loading.load_on_pk_identity)
  File "/home/lutz/Development/databas/venv/lib/python3.6/site-packages/sqlalchemy/orm/query.py", line 1119, in _get_impl
    return db_load_fn(self, primary_key_identity)
  File "/home/lutz/Development/databas/venv/lib/python3.6/site-packages/sqlalchemy/orm/loading.py", line 284, in load_on_pk_identity
    return q.one()
  File "/home/lutz/Development/databas/venv/lib/python3.6/site-packages/sqlalchemy/orm/query.py", line 3358, in one
    ret = self.one_or_none()
  File "/home/lutz/Development/databas/venv/lib/python3.6/site-packages/sqlalchemy/orm/query.py", line 3327, in one_or_none
    ret = list(self)
  File "/home/lutz/Development/databas/venv/lib/python3.6/site-packages/sqlalchemy/orm/query.py", line 3403, in __iter__
    return self._execute_and_instances(context)
  File "/home/lutz/Development/databas/venv/lib/python3.6/site-packages/sqlalchemy/orm/query.py", line 3428, in _execute_and_instances
    result = conn.execute(querycontext.statement, self._params)
  File "/home/lutz/Development/databas/venv/lib/python3.6/site-packages/sqlalchemy/engine/base.py", line 984, in execute
    return meth(self, multiparams, params)
  File "/home/lutz/Development/databas/venv/lib/python3.6/site-packages/sqlalchemy/sql/elements.py", line 293, in _execute_on_connection
    return connection._execute_clauseelement(self, multiparams, params)
  File "/home/lutz/Development/databas/venv/lib/python3.6/site-packages/sqlalchemy/engine/base.py", line 1103, in _execute_clauseelement
    distilled_params,
  File "/home/lutz/Development/databas/venv/lib/python3.6/site-packages/sqlalchemy/engine/base.py", line 1288, in _execute_context
    e, statement, parameters, cursor, context
  File "/home/lutz/Development/databas/venv/lib/python3.6/site-packages/sqlalchemy/engine/base.py", line 1482, in _handle_dbapi_exception
    sqlalchemy_exception, with_traceback=exc_info[2], from_=e
  File "/home/lutz/Development/databas/venv/lib/python3.6/site-packages/sqlalchemy/util/compat.py", line 178, in raise_
    raise exception
  File "/home/lutz/Development/databas/venv/lib/python3.6/site-packages/sqlalchemy/engine/base.py", line 1248, in _execute_context
    cursor, statement, parameters, context
  File "/home/lutz/Development/databas/venv/lib/python3.6/site-packages/sqlalchemy/engine/default.py", line 588, in do_execute
    cursor.execute(statement, parameters)
sqlalchemy.exc.OperationalError: (sqlite3.OperationalError) no such column: user.isAdmin
[SQL: SELECT user.id AS user_id, user.username AS user_username, user.email AS user_email, user.password_hash AS user_password_hash, user.about_me AS user_about_me, user."isAdmin" AS "user_isAdmin", user.last_seen AS user_last_seen 
FROM user 
WHERE user.id = ?]
[parameters: (1,)]
(Background on this error at: http://sqlalche.me/e/e3q8)
2020-04-24 17:34:33,705 INFO: Microblog startup [in /home/lutz/Development/databas/app/__init__.py:47]
2020-04-24 17:34:46,581 INFO: Microblog startup [in /home/lutz/Development/databas/app/__init__.py:47]
2020-04-24 17:35:06,434 INFO: Microblog startup [in /home/lutz/Development/databas/app/__init__.py:47]
2020-04-24 17:35:16,777 INFO: Microblog startup [in /home/lutz/Development/databas/app/__init__.py:47]
2020-04-24 17:35:28,639 INFO: Microblog startup [in /home/lutz/Development/databas/app/__init__.py:47]
2020-04-24 17:35:35,695 INFO: Microblog startup [in /home/lutz/Development/databas/app/__init__.py:47]
2020-04-24 17:35:38,511 INFO: Microblog startup [in /home/lutz/Development/databas/app/__init__.py:47]
2020-04-24 17:52:26,304 INFO: Microblog startup [in /home/lutz/Development/databas/app/__init__.py:47]
2020-04-24 17:53:39,009 INFO: Microblog startup [in /home/lutz/Development/databas/app/__init__.py:47]
